2019-03-14 15:19:04,732 ERROR: Exception on /location [POST] [in /Users/kymanilawrence/Documents/artwork_prov/venv/lib/python3.7/site-packages/flask/app.py:1761]
Traceback (most recent call last):
  File "/Users/kymanilawrence/Documents/artwork_prov/venv/lib/python3.7/site-packages/rdflib/plugin.py", line 100, in get
    p = _plugins[(name, kind)]
KeyError: ('rdf', <class 'rdflib.parser.Parser'>)

During handling of the above exception, another exception occurred:

Traceback (most recent call last):
  File "/Users/kymanilawrence/Documents/artwork_prov/venv/lib/python3.7/site-packages/flask/app.py", line 2292, in wsgi_app
    response = self.full_dispatch_request()
  File "/Users/kymanilawrence/Documents/artwork_prov/venv/lib/python3.7/site-packages/flask/app.py", line 1815, in full_dispatch_request
    rv = self.handle_user_exception(e)
  File "/Users/kymanilawrence/Documents/artwork_prov/venv/lib/python3.7/site-packages/flask/app.py", line 1718, in handle_user_exception
    reraise(exc_type, exc_value, tb)
  File "/Users/kymanilawrence/Documents/artwork_prov/venv/lib/python3.7/site-packages/flask/_compat.py", line 35, in reraise
    raise value
  File "/Users/kymanilawrence/Documents/artwork_prov/venv/lib/python3.7/site-packages/flask/app.py", line 1813, in full_dispatch_request
    rv = self.dispatch_request()
  File "/Users/kymanilawrence/Documents/artwork_prov/venv/lib/python3.7/site-packages/flask/app.py", line 1799, in dispatch_request
    return self.view_functions[rule.endpoint](**req.view_args)
  File "/Users/kymanilawrence/Documents/artwork_prov/app/queries.py", line 32, in locationQuery
    g.parse(outputfile, format='rdf')
  File "/Users/kymanilawrence/Documents/artwork_prov/venv/lib/python3.7/site-packages/rdflib/graph.py", line 1041, in parse
    parser = plugin.get(format, Parser)()
  File "/Users/kymanilawrence/Documents/artwork_prov/venv/lib/python3.7/site-packages/rdflib/plugin.py", line 103, in get
    "No plugin registered for (%s, %s)" % (name, kind))
rdflib.plugin.PluginException: No plugin registered for (rdf, <class 'rdflib.parser.Parser'>)
2019-03-14 15:20:11,623 INFO: Artwork Prov startup [in /Users/kymanilawrence/Documents/artwork_prov/app/__init__.py:45]
2019-03-14 15:26:09,349 INFO: Artwork Prov startup [in /Users/kymanilawrence/Documents/artwork_prov/app/__init__.py:45]
2019-03-14 16:05:28,648 INFO: Artwork Prov startup [in /Users/kymanilawrence/Documents/artwork_prov/app/__init__.py:45]
2019-03-14 16:13:09,755 INFO: Artwork Prov startup [in /Users/kymanilawrence/Documents/artwork_prov/app/__init__.py:45]
2019-03-14 16:14:32,333 INFO: Artwork Prov startup [in /Users/kymanilawrence/Documents/artwork_prov/app/__init__.py:45]
2019-03-14 16:17:27,275 INFO: Artwork Prov startup [in /Users/kymanilawrence/Documents/artwork_prov/app/__init__.py:45]
2019-03-14 17:04:54,403 INFO: Artwork Prov startup [in /Users/kymanilawrence/Documents/artwork_prov/app/__init__.py:45]
2019-03-14 17:09:32,486 INFO: Artwork Prov startup [in /Users/kymanilawrence/Documents/artwork_prov/app/__init__.py:45]
2019-03-14 17:12:09,206 INFO: Artwork Prov startup [in /Users/kymanilawrence/Documents/artwork_prov/app/__init__.py:45]
2019-03-14 17:12:15,050 ERROR: Exception on /location [POST] [in /Users/kymanilawrence/Documents/artwork_prov/venv/lib/python3.7/site-packages/flask/app.py:1761]
Traceback (most recent call last):
  File "/Users/kymanilawrence/Documents/artwork_prov/venv/lib/python3.7/site-packages/rdflib/plugin.py", line 100, in get
    p = _plugins[(name, kind)]
KeyError: ('xml', <class 'rdflib.query.Result'>)

During handling of the above exception, another exception occurred:

Traceback (most recent call last):
  File "/Users/kymanilawrence/Documents/artwork_prov/venv/lib/python3.7/site-packages/flask/app.py", line 2292, in wsgi_app
    response = self.full_dispatch_request()
  File "/Users/kymanilawrence/Documents/artwork_prov/venv/lib/python3.7/site-packages/flask/app.py", line 1815, in full_dispatch_request
    rv = self.handle_user_exception(e)
  File "/Users/kymanilawrence/Documents/artwork_prov/venv/lib/python3.7/site-packages/flask/app.py", line 1718, in handle_user_exception
    reraise(exc_type, exc_value, tb)
  File "/Users/kymanilawrence/Documents/artwork_prov/venv/lib/python3.7/site-packages/flask/_compat.py", line 35, in reraise
    raise value
  File "/Users/kymanilawrence/Documents/artwork_prov/venv/lib/python3.7/site-packages/flask/app.py", line 1813, in full_dispatch_request
    rv = self.dispatch_request()
  File "/Users/kymanilawrence/Documents/artwork_prov/venv/lib/python3.7/site-packages/flask/app.py", line 1799, in dispatch_request
    return self.view_functions[rule.endpoint](**req.view_args)
  File "/Users/kymanilawrence/Documents/artwork_prov/app/queries.py", line 37, in locationQuery
    }""", result='xml')
  File "/Users/kymanilawrence/Documents/artwork_prov/venv/lib/python3.7/site-packages/rdflib/graph.py", line 1084, in query
    result = plugin.get(result, query.Result)
  File "/Users/kymanilawrence/Documents/artwork_prov/venv/lib/python3.7/site-packages/rdflib/plugin.py", line 103, in get
    "No plugin registered for (%s, %s)" % (name, kind))
rdflib.plugin.PluginException: No plugin registered for (xml, <class 'rdflib.query.Result'>)
2019-03-14 17:15:31,342 INFO: Artwork Prov startup [in /Users/kymanilawrence/Documents/artwork_prov/app/__init__.py:45]
2019-03-14 17:21:06,047 INFO: Artwork Prov startup [in /Users/kymanilawrence/Documents/artwork_prov/app/__init__.py:45]
2019-03-14 17:30:28,712 INFO: Artwork Prov startup [in /Users/kymanilawrence/Documents/artwork_prov/app/__init__.py:45]
2019-03-14 19:17:58,044 INFO: Artwork Prov startup [in /Users/kymanilawrence/Documents/artwork_prov/app/__init__.py:45]
2019-03-14 19:19:01,766 INFO: Artwork Prov startup [in /Users/kymanilawrence/Documents/artwork_prov/app/__init__.py:45]
2019-03-14 19:52:17,539 INFO: Artwork Prov startup [in /Users/kymanilawrence/Documents/artwork_prov/app/__init__.py:45]
