2019-03-14 14:54:22,333 ERROR: Exception on /location [POST] [in /Users/kymanilawrence/Documents/artwork_prov/venv/lib/python3.7/site-packages/flask/app.py:1761]
Traceback (most recent call last):
  File "/usr/local/Cellar/python/3.7.2_1/Frameworks/Python.framework/Versions/3.7/lib/python3.7/shutil.py", line 563, in move
    os.rename(src, real_dst)
FileNotFoundError: [Errno 2] No such file or directory: '/var/folders/k6/n6jf9vmd3g16fgncqpzz4_680000gn/T/tmpiqsgmklm' -> 'rdfqueryfiles/JofferyLand'

During handling of the above exception, another exception occurred:

Traceback (most recent call last):
  File "/Users/kymanilawrence/Documents/artwork_prov/venv/lib/python3.7/site-packages/flask/app.py", line 2292, in wsgi_app
    response = self.full_dispatch_request()
  File "/Users/kymanilawrence/Documents/artwork_prov/venv/lib/python3.7/site-packages/flask/app.py", line 1815, in full_dispatch_request
    rv = self.handle_user_exception(e)
  File "/Users/kymanilawrence/Documents/artwork_prov/venv/lib/python3.7/site-packages/flask/app.py", line 1718, in handle_user_exception
    reraise(exc_type, exc_value, tb)
  File "/Users/kymanilawrence/Documents/artwork_prov/venv/lib/python3.7/site-packages/flask/_compat.py", line 35, in reraise
    raise value
  File "/Users/kymanilawrence/Documents/artwork_prov/venv/lib/python3.7/site-packages/flask/app.py", line 1813, in full_dispatch_request
    rv = self.dispatch_request()
  File "/Users/kymanilawrence/Documents/artwork_prov/venv/lib/python3.7/site-packages/flask/app.py", line 1799, in dispatch_request
    return self.view_functions[rule.endpoint](**req.view_args)
  File "/Users/kymanilawrence/Documents/artwork_prov/app/queries.py", line 26, in locationQuery
    provn_doc.serialize('rdfqueryfiles/'+filename, format='rdf')
  File "/Users/kymanilawrence/Documents/artwork_prov/venv/lib/python3.7/site-packages/prov/model.py", line 2407, in serialize
    shutil.move(name, path)
  File "/usr/local/Cellar/python/3.7.2_1/Frameworks/Python.framework/Versions/3.7/lib/python3.7/shutil.py", line 577, in move
    copy_function(src, real_dst)
  File "/usr/local/Cellar/python/3.7.2_1/Frameworks/Python.framework/Versions/3.7/lib/python3.7/shutil.py", line 263, in copy2
    copyfile(src, dst, follow_symlinks=follow_symlinks)
  File "/usr/local/Cellar/python/3.7.2_1/Frameworks/Python.framework/Versions/3.7/lib/python3.7/shutil.py", line 121, in copyfile
    with open(dst, 'wb') as fdst:
FileNotFoundError: [Errno 2] No such file or directory: 'rdfqueryfiles/JofferyLand'
2019-03-14 14:57:38,245 INFO: Artwork Prov startup [in /Users/kymanilawrence/Documents/artwork_prov/app/__init__.py:45]
2019-03-14 15:03:46,836 INFO: Artwork Prov startup [in /Users/kymanilawrence/Documents/artwork_prov/app/__init__.py:45]
2019-03-14 15:06:10,726 INFO: Artwork Prov startup [in /Users/kymanilawrence/Documents/artwork_prov/app/__init__.py:45]
2019-03-14 15:06:47,574 INFO: Artwork Prov startup [in /Users/kymanilawrence/Documents/artwork_prov/app/__init__.py:45]
2019-03-14 15:06:54,141 ERROR: Exception on /location [POST] [in /Users/kymanilawrence/Documents/artwork_prov/venv/lib/python3.7/site-packages/flask/app.py:1761]
Traceback (most recent call last):
  File "/usr/local/Cellar/python/3.7.2_1/Frameworks/Python.framework/Versions/3.7/lib/python3.7/shutil.py", line 563, in move
    os.rename(src, real_dst)
FileNotFoundError: [Errno 2] No such file or directory: '/var/folders/k6/n6jf9vmd3g16fgncqpzz4_680000gn/T/tmpvf42dnd_' -> '/Users/kymanilawrence/Documents/artwork_prov/rdfqueryfiles/JofferyLand.rdf'

During handling of the above exception, another exception occurred:

Traceback (most recent call last):
  File "/Users/kymanilawrence/Documents/artwork_prov/venv/lib/python3.7/site-packages/flask/app.py", line 2292, in wsgi_app
    response = self.full_dispatch_request()
  File "/Users/kymanilawrence/Documents/artwork_prov/venv/lib/python3.7/site-packages/flask/app.py", line 1815, in full_dispatch_request
    rv = self.handle_user_exception(e)
  File "/Users/kymanilawrence/Documents/artwork_prov/venv/lib/python3.7/site-packages/flask/app.py", line 1718, in handle_user_exception
    reraise(exc_type, exc_value, tb)
  File "/Users/kymanilawrence/Documents/artwork_prov/venv/lib/python3.7/site-packages/flask/_compat.py", line 35, in reraise
    raise value
  File "/Users/kymanilawrence/Documents/artwork_prov/venv/lib/python3.7/site-packages/flask/app.py", line 1813, in full_dispatch_request
    rv = self.dispatch_request()
  File "/Users/kymanilawrence/Documents/artwork_prov/venv/lib/python3.7/site-packages/flask/app.py", line 1799, in dispatch_request
    return self.view_functions[rule.endpoint](**req.view_args)
  File "/Users/kymanilawrence/Documents/artwork_prov/app/queries.py", line 29, in locationQuery
    provn_doc.serialize(outputfile, format='rdf')
  File "/Users/kymanilawrence/Documents/artwork_prov/venv/lib/python3.7/site-packages/prov/model.py", line 2407, in serialize
    shutil.move(name, path)
  File "/usr/local/Cellar/python/3.7.2_1/Frameworks/Python.framework/Versions/3.7/lib/python3.7/shutil.py", line 577, in move
    copy_function(src, real_dst)
  File "/usr/local/Cellar/python/3.7.2_1/Frameworks/Python.framework/Versions/3.7/lib/python3.7/shutil.py", line 263, in copy2
    copyfile(src, dst, follow_symlinks=follow_symlinks)
  File "/usr/local/Cellar/python/3.7.2_1/Frameworks/Python.framework/Versions/3.7/lib/python3.7/shutil.py", line 121, in copyfile
    with open(dst, 'wb') as fdst:
FileNotFoundError: [Errno 2] No such file or directory: '/Users/kymanilawrence/Documents/artwork_prov/rdfqueryfiles/JofferyLand.rdf'
2019-03-14 15:07:35,168 INFO: Artwork Prov startup [in /Users/kymanilawrence/Documents/artwork_prov/app/__init__.py:45]
2019-03-14 15:08:04,935 INFO: Artwork Prov startup [in /Users/kymanilawrence/Documents/artwork_prov/app/__init__.py:45]
2019-03-14 15:09:23,332 INFO: Artwork Prov startup [in /Users/kymanilawrence/Documents/artwork_prov/app/__init__.py:45]
2019-03-14 15:09:28,598 ERROR: Exception on /location [POST] [in /Users/kymanilawrence/Documents/artwork_prov/venv/lib/python3.7/site-packages/flask/app.py:1761]
Traceback (most recent call last):
  File "/Users/kymanilawrence/Documents/artwork_prov/venv/lib/python3.7/site-packages/flask/app.py", line 2292, in wsgi_app
    response = self.full_dispatch_request()
  File "/Users/kymanilawrence/Documents/artwork_prov/venv/lib/python3.7/site-packages/flask/app.py", line 1815, in full_dispatch_request
    rv = self.handle_user_exception(e)
  File "/Users/kymanilawrence/Documents/artwork_prov/venv/lib/python3.7/site-packages/flask/app.py", line 1718, in handle_user_exception
    reraise(exc_type, exc_value, tb)
  File "/Users/kymanilawrence/Documents/artwork_prov/venv/lib/python3.7/site-packages/flask/_compat.py", line 35, in reraise
    raise value
  File "/Users/kymanilawrence/Documents/artwork_prov/venv/lib/python3.7/site-packages/flask/app.py", line 1813, in full_dispatch_request
    rv = self.dispatch_request()
  File "/Users/kymanilawrence/Documents/artwork_prov/venv/lib/python3.7/site-packages/flask/app.py", line 1799, in dispatch_request
    return self.view_functions[rule.endpoint](**req.view_args)
  File "/Users/kymanilawrence/Documents/artwork_prov/app/queries.py", line 32, in locationQuery
    g.parse('../rdfqueryfiles/'+filename+'.rdf')
  File "/Users/kymanilawrence/Documents/artwork_prov/venv/lib/python3.7/site-packages/rdflib/graph.py", line 1034, in parse
    data=data, format=format)
  File "/Users/kymanilawrence/Documents/artwork_prov/venv/lib/python3.7/site-packages/rdflib/parser.py", line 184, in create_input_source
    file = open(filename, "rb")
NotADirectoryError: [Errno 20] Not a directory: '/Users/kymanilawrence/Documents/rdfqueryfiles/JofferyLand.rdf'
2019-03-14 15:10:00,257 INFO: Artwork Prov startup [in /Users/kymanilawrence/Documents/artwork_prov/app/__init__.py:45]
