2019-02-20 15:59:21,308 ERROR: Exception on /newtransaction [POST] [in /Users/kymanilawrence/Documents/artwork_prov/venv/lib/python3.7/site-packages/flask/app.py:1761]
Traceback (most recent call last):
  File "/Users/kymanilawrence/Documents/artwork_prov/venv/lib/python3.7/site-packages/flask/app.py", line 2292, in wsgi_app
    response = self.full_dispatch_request()
  File "/Users/kymanilawrence/Documents/artwork_prov/venv/lib/python3.7/site-packages/flask/app.py", line 1815, in full_dispatch_request
    rv = self.handle_user_exception(e)
  File "/Users/kymanilawrence/Documents/artwork_prov/venv/lib/python3.7/site-packages/flask/app.py", line 1718, in handle_user_exception
    reraise(exc_type, exc_value, tb)
  File "/Users/kymanilawrence/Documents/artwork_prov/venv/lib/python3.7/site-packages/flask/_compat.py", line 35, in reraise
    raise value
  File "/Users/kymanilawrence/Documents/artwork_prov/venv/lib/python3.7/site-packages/flask/app.py", line 1813, in full_dispatch_request
    rv = self.dispatch_request()
  File "/Users/kymanilawrence/Documents/artwork_prov/venv/lib/python3.7/site-packages/flask/app.py", line 1799, in dispatch_request
    return self.view_functions[rule.endpoint](**req.view_args)
  File "/Users/kymanilawrence/Documents/artwork_prov/app/blockchain.py", line 116, in newtransaction
    Provenance.new_art()
AttributeError: type object 'Provenance' has no attribute 'new_art'
2019-02-20 16:00:22,159 INFO: Artwork Prov startup [in /Users/kymanilawrence/Documents/artwork_prov/app/__init__.py:45]
2019-02-20 16:00:54,582 ERROR: Exception on /newtransaction [POST] [in /Users/kymanilawrence/Documents/artwork_prov/venv/lib/python3.7/site-packages/flask/app.py:1761]
Traceback (most recent call last):
  File "/Users/kymanilawrence/Documents/artwork_prov/venv/lib/python3.7/site-packages/flask/app.py", line 2292, in wsgi_app
    response = self.full_dispatch_request()
  File "/Users/kymanilawrence/Documents/artwork_prov/venv/lib/python3.7/site-packages/flask/app.py", line 1815, in full_dispatch_request
    rv = self.handle_user_exception(e)
  File "/Users/kymanilawrence/Documents/artwork_prov/venv/lib/python3.7/site-packages/flask/app.py", line 1718, in handle_user_exception
    reraise(exc_type, exc_value, tb)
  File "/Users/kymanilawrence/Documents/artwork_prov/venv/lib/python3.7/site-packages/flask/_compat.py", line 35, in reraise
    raise value
  File "/Users/kymanilawrence/Documents/artwork_prov/venv/lib/python3.7/site-packages/flask/app.py", line 1813, in full_dispatch_request
    rv = self.dispatch_request()
  File "/Users/kymanilawrence/Documents/artwork_prov/venv/lib/python3.7/site-packages/flask/app.py", line 1799, in dispatch_request
    return self.view_functions[rule.endpoint](**req.view_args)
  File "/Users/kymanilawrence/Documents/artwork_prov/app/blockchain.py", line 116, in newtransaction
    new_art()
  File "/Users/kymanilawrence/Documents/artwork_prov/app/provenance.py", line 24, in new_art
    newprov.document.entity('art:' + transaction['artid'], {
TypeError: list indices must be integers or slices, not str
2019-02-20 16:17:17,876 INFO: Artwork Prov startup [in /Users/kymanilawrence/Documents/artwork_prov/app/__init__.py:45]
2019-02-20 16:17:45,586 ERROR: Exception on /newtransaction [POST] [in /Users/kymanilawrence/Documents/artwork_prov/venv/lib/python3.7/site-packages/flask/app.py:1761]
Traceback (most recent call last):
  File "/Users/kymanilawrence/Documents/artwork_prov/venv/lib/python3.7/site-packages/flask/app.py", line 2292, in wsgi_app
    response = self.full_dispatch_request()
  File "/Users/kymanilawrence/Documents/artwork_prov/venv/lib/python3.7/site-packages/flask/app.py", line 1815, in full_dispatch_request
    rv = self.handle_user_exception(e)
  File "/Users/kymanilawrence/Documents/artwork_prov/venv/lib/python3.7/site-packages/flask/app.py", line 1718, in handle_user_exception
    reraise(exc_type, exc_value, tb)
  File "/Users/kymanilawrence/Documents/artwork_prov/venv/lib/python3.7/site-packages/flask/_compat.py", line 35, in reraise
    raise value
  File "/Users/kymanilawrence/Documents/artwork_prov/venv/lib/python3.7/site-packages/flask/app.py", line 1813, in full_dispatch_request
    rv = self.dispatch_request()
  File "/Users/kymanilawrence/Documents/artwork_prov/venv/lib/python3.7/site-packages/flask/app.py", line 1799, in dispatch_request
    return self.view_functions[rule.endpoint](**req.view_args)
  File "/Users/kymanilawrence/Documents/artwork_prov/app/blockchain.py", line 116, in newtransaction
    new_art()
  File "/Users/kymanilawrence/Documents/artwork_prov/app/provenance.py", line 24, in new_art
    newprov.document.entity('art:' + transaction[0], {
TypeError: can only concatenate str (not "dict") to str
2019-02-20 16:19:41,528 INFO: Artwork Prov startup [in /Users/kymanilawrence/Documents/artwork_prov/app/__init__.py:45]
2019-02-20 16:20:06,132 ERROR: Exception on /newtransaction [POST] [in /Users/kymanilawrence/Documents/artwork_prov/venv/lib/python3.7/site-packages/flask/app.py:1761]
Traceback (most recent call last):
  File "/Users/kymanilawrence/Documents/artwork_prov/venv/lib/python3.7/site-packages/flask/app.py", line 2292, in wsgi_app
    response = self.full_dispatch_request()
  File "/Users/kymanilawrence/Documents/artwork_prov/venv/lib/python3.7/site-packages/flask/app.py", line 1815, in full_dispatch_request
    rv = self.handle_user_exception(e)
  File "/Users/kymanilawrence/Documents/artwork_prov/venv/lib/python3.7/site-packages/flask/app.py", line 1718, in handle_user_exception
    reraise(exc_type, exc_value, tb)
  File "/Users/kymanilawrence/Documents/artwork_prov/venv/lib/python3.7/site-packages/flask/_compat.py", line 35, in reraise
    raise value
  File "/Users/kymanilawrence/Documents/artwork_prov/venv/lib/python3.7/site-packages/flask/app.py", line 1813, in full_dispatch_request
    rv = self.dispatch_request()
  File "/Users/kymanilawrence/Documents/artwork_prov/venv/lib/python3.7/site-packages/flask/app.py", line 1799, in dispatch_request
    return self.view_functions[rule.endpoint](**req.view_args)
  File "/Users/kymanilawrence/Documents/artwork_prov/app/blockchain.py", line 116, in newtransaction
    new_art()
  File "/Users/kymanilawrence/Documents/artwork_prov/app/provenance.py", line 25, in new_art
    'art:name': transaction[1],
IndexError: list index out of range
2019-02-20 18:05:55,673 INFO: Artwork Prov startup [in /Users/kymanilawrence/Documents/artwork_prov/app/__init__.py:45]
2019-02-20 18:06:22,308 ERROR: Exception on /newtransaction [POST] [in /Users/kymanilawrence/Documents/artwork_prov/venv/lib/python3.7/site-packages/flask/app.py:1761]
Traceback (most recent call last):
  File "/Users/kymanilawrence/Documents/artwork_prov/venv/lib/python3.7/site-packages/flask/app.py", line 2292, in wsgi_app
    response = self.full_dispatch_request()
  File "/Users/kymanilawrence/Documents/artwork_prov/venv/lib/python3.7/site-packages/flask/app.py", line 1815, in full_dispatch_request
    rv = self.handle_user_exception(e)
  File "/Users/kymanilawrence/Documents/artwork_prov/venv/lib/python3.7/site-packages/flask/app.py", line 1718, in handle_user_exception
    reraise(exc_type, exc_value, tb)
  File "/Users/kymanilawrence/Documents/artwork_prov/venv/lib/python3.7/site-packages/flask/_compat.py", line 35, in reraise
    raise value
  File "/Users/kymanilawrence/Documents/artwork_prov/venv/lib/python3.7/site-packages/flask/app.py", line 1813, in full_dispatch_request
    rv = self.dispatch_request()
  File "/Users/kymanilawrence/Documents/artwork_prov/venv/lib/python3.7/site-packages/flask/app.py", line 1799, in dispatch_request
    return self.view_functions[rule.endpoint](**req.view_args)
  File "/Users/kymanilawrence/Documents/artwork_prov/app/blockchain.py", line 116, in newtransaction
    new_art()
  File "/Users/kymanilawrence/Documents/artwork_prov/app/provenance.py", line 31, in new_art
    'art:weight': labels['weight']
  File "/Users/kymanilawrence/Documents/artwork_prov/venv/lib/python3.7/site-packages/prov/model.py", line 1632, in entity
    return self.new_record(PROV_ENTITY, identifier, None, other_attributes)
  File "/Users/kymanilawrence/Documents/artwork_prov/venv/lib/python3.7/site-packages/prov/model.py", line 1608, in new_record
    self, self.valid_qualified_name(identifier), attr_list
  File "/Users/kymanilawrence/Documents/artwork_prov/venv/lib/python3.7/site-packages/prov/model.py", line 554, in __init__
    raise ProvElementIdentifierRequired()
prov.model.ProvElementIdentifierRequired: An identifier is missing. All PROV elements require a valid identifier.
2019-02-20 21:46:57,640 INFO: Artwork Prov startup [in /Users/kymanilawrence/Documents/artwork_prov/app/__init__.py:45]
